






































































































































































































































































































































































































































































































































































































































































































































































































































































































































































































































Training attention_w0.01_c0:  10%|â–ˆâ–ˆâ–ˆâ–ˆâ–ˆâ–ˆâ–ˆ                                                               | 1000/10000 [8:43:59<78:35:55, 31.44s/it, avg_reward=750.20, influence_w=0.010]
[34m[1mwandb[39m[22m: [32m[41mERROR[39m[49m Permission denied to access kaoutar-et-tamadit-ibn-tofail/social-influence-marl/lezd809m
Traceback (most recent call last):
  File "/home/kaou-internship/anaconda3/envs/binf/lib/python3.8/site-packages/wandb/sdk/lib/retry.py", line 113, in __call__
    result = self._call_fn(*args, **kwargs)
  File "/home/kaou-internship/anaconda3/envs/binf/lib/python3.8/site-packages/wandb/apis/public.py", line 226, in execute
    return self._client.execute(*args, **kwargs)
  File "/home/kaou-internship/anaconda3/envs/binf/lib/python3.8/site-packages/wandb/vendor/gql-0.2.0/wandb_gql/client.py", line 52, in execute
    result = self._get_result(document, *args, **kwargs)
  File "/home/kaou-internship/anaconda3/envs/binf/lib/python3.8/site-packages/wandb/vendor/gql-0.2.0/wandb_gql/client.py", line 60, in _get_result
    return self.transport.execute(document, *args, **kwargs)
  File "/home/kaou-internship/anaconda3/envs/binf/lib/python3.8/site-packages/wandb/vendor/gql-0.2.0/wandb_gql/transport/requests.py", line 39, in execute
    request.raise_for_status()
  File "/home/kaou-internship/anaconda3/envs/binf/lib/python3.8/site-packages/requests/models.py", line 1024, in raise_for_status
    raise HTTPError(http_error_msg, response=self)
requests.exceptions.HTTPError: 404 Client Error: Not Found for url: https://api.wandb.ai/graphql
During handling of the above exception, another exception occurred:
Traceback (most recent call last):
  File "train.py", line 209, in <module>
    main()
  File "train.py", line 188, in main
    exp_dir = run_experiments('harvest', args)
  File "train.py", line 124, in run_experiments
    results = runner.run_all_experiments(args.models)
  File "/home/kaou-internship/basic_influence_attention/experiments/runner.py", line 321, in run_all_experiments
    results = self.run_single_experiment(config, seed)
  File "/home/kaou-internship/basic_influence_attention/experiments/runner.py", line 205, in run_single_experiment
    wandb.log_artifact(artifact)
  File "/home/kaou-internship/anaconda3/envs/binf/lib/python3.8/site-packages/wandb/sdk/wandb_run.py", line 255, in wrapper
    return func(self, *args, **kwargs)
  File "/home/kaou-internship/anaconda3/envs/binf/lib/python3.8/site-packages/wandb/sdk/wandb_run.py", line 2600, in log_artifact
    return self._log_artifact(
  File "/home/kaou-internship/anaconda3/envs/binf/lib/python3.8/site-packages/wandb/sdk/wandb_run.py", line 2737, in _log_artifact
    self._assert_can_log_artifact(artifact)
  File "/home/kaou-internship/anaconda3/envs/binf/lib/python3.8/site-packages/wandb/sdk/wandb_run.py", line 2783, in _assert_can_log_artifact
    expected_type = public.Artifact.expected_type(
  File "/home/kaou-internship/anaconda3/envs/binf/lib/python3.8/site-packages/wandb/apis/public.py", line 4152, in expected_type
    response = client.execute(
  File "/home/kaou-internship/anaconda3/envs/binf/lib/python3.8/site-packages/wandb/sdk/lib/retry.py", line 190, in wrapped_fn
    return retrier(*args, **kargs)
  File "/home/kaou-internship/anaconda3/envs/binf/lib/python3.8/site-packages/wandb/sdk/lib/retry.py", line 129, in __call__
    retry_timedelta_triggered = check_retry_fn(e)
  File "/home/kaou-internship/anaconda3/envs/binf/lib/python3.8/site-packages/wandb/util.py", line 887, in no_retry_auth
    raise CommError(f"Permission denied to access {wandb.run.path}")
wandb.errors.CommError: Permission denied to access kaoutar-et-tamadit-ibn-tofail/social-influence-marl/lezd809m